Workbook

Sheet raw_customers
A1: CUSTOMER_ID | B1: FULL_NAME | C1: GENDER | D1: BIRTH_DATE | E1: CITY | F1: BRANCH_ID | G1: SEGMENT | H1: JOIN_DATE
A2: 478 | B2: Zaur Tağıyev | C2: M | D2: 1970-07-16 00:00:00.000 | E2: Sumqayıt | F2: 4 | G2: Retail | H2: 2024-10-21 00:00:00.000
A3: 479 | B3: Samir Əliyev | C3: M | D3: 1981-04-07 00:00:00.000 | E3: Bakı | F3: 2 | G3: Premium | H3: 2019-08-29 00:00:00.000
A4: 480 | B4: Zeynəb Nəbiyev | C4: F | D4: 1968-12-18 00:00:00.000 | E4: Bakı | F4: 2 | G4: Retail | H4: 2020-05-08 00:00:00.000
A5: 481 | B5: Fuad Cəfərov | C5: M | D5: 1973-10-14 00:00:00.000 | E5: Bakı | F5: 2 | G5: SME | H5: 2021-11-13 00:00:00.000
A6: 482 | B6: Leyla Məmmədov | C6: F | D6: 1982-08-15 00:00:00.000 | E6: Şəki | F6: 6 | G6: Retail | H6: 2019-12-04 00:00:00.000
A7: 483 | B7: Nicat Sadıqov | C7: M | D7: 1978-07-13 00:00:00.000 | E7: Lənkəran | F7: 7 | G7: Retail | H7: 2024-03-18 00:00:00.000
A8: 484 | B8: Emin Nəbiyev | C8: M | D8: 1975-06-06 00:00:00.000 | E8: Bakı | F8: 1 | G8: SME | H8: 2023-10-05 00:00:00.000
A9: 485 | B9: Nigar Nəbiyev | C9: F | D9: 1982-11-03 00:00:00.000 | E9: Bakı | F9: 2 | G9: Retail | H9: 2019-07-12 00:00:00.000
A10: 486 | B10: Leyla Əzizov | C10: F | D10: 1975-07-23 00:00:00.000 | E10: Gəncə | F10: 3 | G10: Retail | H10: 2021-02-20 00:00:00.000
A11: 487 | B11: Anar Cəfərov | C11: M | D11: 1968-10-10 00:00:00.000 | E11: Sumqayıt | F11: 4 | G11: SME | H11: 2022-11-12 00:00:00.000
A12: 488 | B12: Rəşad Abbasov | C12: M | D12: 1975-11-16 00:00:00.000 | E12: Sumqayıt | F12: 4 | G12: Retail | H12: 2022-09-22 00:00:00.000
A13: 489 | B13: Röya Rzayev | C13: F | D13: 1974-09-08 00:00:00.000 | E13: Mingəçevir | F13: 5 | G13: Premium | H13: 2021-01-29 00:00:00.000
... A1001: 832 | B1001: Fidan Rzayev | C1001: F | D1001: 1970-03-22 00:00:00.000 | E1001: Sumqayıt | F1001: 4 | G1001: Retail | H1001: 2024-10-14 00:00:00.000

Sheet raw_loans
A1: LOAN_ID | B1: CUSTOMER_ID | C1: BRANCH_ID | D1: LOAN_TYPE | E1: LOAN_AMOUNT | F1: INTEREST_RATE | G1: TERM_MONTHS | H1: START_DATE | I1: STATUS | J1: DAYS_PAST_DUE | K1: FIXED-START_DATE | L1: FIXED_LOAN_AMOUNT
A2: 503 | B2: 964 | C2: 3 | D2: Business Loan | E2: 144802.01 | F2: 12.52 | G2: 38 | H2: 2023-10-12 00:00:00.000 | I2: Active | J2: 44 | K2: =DATEVALUE(LEFT(H2,10)) -> 45211 | L2: =_xlfn.NUMBERVALUE(E2,".",",") -> 14480201
A3: 504 | B3: 702 | C3: 2 | D3: Business Loan | E3: 79987.33 | F3: 16.44 | G3: 115 | H3: 2020-05-20 00:00:00.000 | I3: Active | J3: 0 | K3: =DATEVALUE(LEFT(H3,10)) -> 43971 | L3: =_xlfn.NUMBERVALUE(E3,".",",") -> 7998733
A4: 505 | B4: 110 | C4: 7 | D4: Personal Loan | E4: 7888.64 | F4: 9.37 | G4: 57 | H4: 2025-06-17 00:00:00.000 | I4: Active | J4: 71 | K4: =DATEVALUE(LEFT(H4,10)) -> 45825 | L4: =_xlfn.NUMBERVALUE(E4,".",",") -> 788864
A5: 506 | B5: 366 | C5: 1 | D5: Business Loan | E5: 57335.63 | F5: 18.56 | G5: 49 | H5: 2024-11-07 00:00:00.000 | I5: Active | J5: 0 | K5: =DATEVALUE(LEFT(H5,10)) -> 45603 | L5: =_xlfn.NUMBERVALUE(E5,".",",") -> 5733563
A6: 507 | B6: 629 | C6: 2 | D6: Business Loan | E6: 68276.52 | F6: 13.67 | G6: 59 | H6: 2021-09-24 00:00:00.000 | I6: Active | J6: 0 | K6: =DATEVALUE(LEFT(H6,10)) -> 44463 | L6: =_xlfn.NUMBERVALUE(E6,".",",") -> 6827652
A7: 508 | B7: 934 | C7: 2 | D7: Personal Loan | E7: 5395.2 | F7: 16.34 | G7: 55 | H7: 2020-05-05 00:00:00.000 | I7: Closed | J7: 0 | K7: =DATEVALUE(LEFT(H7,10)) -> 43956 | L7: =_xlfn.NUMBERVALUE(E7,".",",") -> 53952
A8: 509 | B8: 907 | C8: 7 | D8: Business Loan | E8: 107604.16 | F8: 19.45 | G8: 53 | H8: 2025-01-06 00:00:00.000 | I8: Active | J8: 0 | K8: =DATEVALUE(LEFT(H8,10)) -> 45663 | L8: =_xlfn.NUMBERVALUE(E8,".",",") -> 10760416
A9: 510 | B9: 326 | C9: 7 | D9: Credit Card | E9: 7430.32 | F9: 12.87 | G9: 6 | H9: 2025-05-30 00:00:00.000 | I9: Active | J9: 0 | K9: =DATEVALUE(LEFT(H9,10)) -> 45807 | L9: =_xlfn.NUMBERVALUE(E9,".",",") -> 743032
A10: 511 | B10: 352 | C10: 7 | D10: Mortgage | E10: 99322.46 | F10: 14.86 | G10: 147 | H10: 2022-07-25 00:00:00.000 | I10: Closed | J10: 0 | K10: =DATEVALUE(LEFT(H10,10)) -> 44767 | L10: =_xlfn.NUMBERVALUE(E10,".",",") -> 9932246
A11: 512 | B11: 979 | C11: 1 | D11: Personal Loan | E11: 14436.78 | F11: 7.81 | G11: 20 | H11: 2023-08-18 00:00:00.000 | I11: Active | J11: 0 | K11: =DATEVALUE(LEFT(H11,10)) -> 45156 | L11: =_xlfn.NUMBERVALUE(E11,".",",") -> 1443678
A12: 513 | B12: 708 | C12: 2 | D12: Mortgage | E12: 106322.24 | F12: 8.32 | G12: 280 | H12: 2023-11-26 00:00:00.000 | I12: Closed | J12: 0 | K12: =DATEVALUE(LEFT(H12,10)) -> 45256 | L12: =_xlfn.NUMBERVALUE(E12,".",",") -> 10632224
A13: 514 | B13: 243 | C13: 6 | D13: Mortgage | E13: 136314.96 | F13: 11.88 | G13: 230 | H13: 2024-12-25 00:00:00.000 | I13: Active | J13: 0 | K13: =DATEVALUE(LEFT(H13,10)) -> 45651 | L13: =_xlfn.NUMBERVALUE(E13,".",",") -> 13631496
... A1301: 877 | B1301: 661 | C1301: 4 | D1301: Mortgage | E1301: 69139.55 | F1301: 12.58 | G1301: 172 | H1301: 2023-06-08 00:00:00.000 | I1301: Default | J1301: 251 | K1301: =DATEVALUE(LEFT(H1301,10)) -> 45085 | L1301: =_xlfn.NUMBERVALUE(E1301,".",",") -> 6913955

Sheet raw_branches
A1: BRANCH_ID | B1: BRANCH_NAME | C1: CITY
A2: 1 | B2: Baku Central | C2: Bakı
A3: 2 | B3: Baku Yasamal | C3: Bakı
A4: 3 | B4: Ganja Branch | C4: Gəncə
A5: 4 | B5: Sumgait Branch | C5: Sumqayıt
A6: 5 | B6: Mingachevir Branch | C6: Mingəçevir
A7: 6 | B7: Sheki Branch | C7: Şəki
A8: 7 | B8: Lankaran Branch | C8: Lənkəran

Sheet analytics_data
A1: LOAN_ID | B1: Customer id | C1: Customer Name | D1: Gender | E1: Customer Segment | F1: Branch Name | G1: Loan Amount | H1: Interest Rate | I1: Loan Status | J1: Risk Category
A2: 503 | B2: 964 | C2: =_xlfn.XLOOKUP(B2,raw_customers!A:A,raw_customers!B:B) -> Murad Sadıqov | D2: =_xlfn.XLOOKUP(C2,raw_customers!B:B,raw_customers!C:C) -> M | E2: =_xlfn.XLOOKUP(C2,raw_customers!B:B,raw_customers!G:G) -> Premium | F2: =_xlfn.XLOOKUP(_xlfn.XLOOKUP(B2,raw_customers!A:A,raw_customers!F:F),raw_branches!A:A,raw_branches!B:B) -> Ganja Branch | G2: 144802.01 | H2: 12.52 | I2: Active | J2: =IF(I2="Default","Default (Batıq)",IF(H2>=18,"Yüksək Risk",IF(H2>=12,"Orta Risk","Aşağı Risk"))) -> Orta Risk
A3: 504 | B3: 702 | C3: =_xlfn.XLOOKUP(B3,raw_customers!A:A,raw_customers!B:B) -> Murad Bağırov | D3: =_xlfn.XLOOKUP(C3,raw_customers!B:B,raw_customers!C:C) -> M | E3: =_xlfn.XLOOKUP(C3,raw_customers!B:B,raw_customers!G:G) -> SME | F3: =_xlfn.XLOOKUP(_xlfn.XLOOKUP(B3,raw_customers!A:A,raw_customers!F:F),raw_branches!A:A,raw_branches!B:B) -> Baku Yasamal | G3: 79987.33 | H3: 16.44 | I3: Active | J3: =IF(I3="Default","Default (Batıq)",IF(H3>=18,"Yüksək Risk",IF(H3>=12,"Orta Risk","Aşağı Risk"))) -> Orta Risk
A4: 505 | B4: 110 | C4: =_xlfn.XLOOKUP(B4,raw_customers!A:A,raw_customers!B:B) -> Xəyalə Hüseynov | D4: =_xlfn.XLOOKUP(C4,raw_customers!B:B,raw_customers!C:C) -> F | E4: =_xlfn.XLOOKUP(C4,raw_customers!B:B,raw_customers!G:G) -> Retail | F4: =_xlfn.XLOOKUP(_xlfn.XLOOKUP(B4,raw_customers!A:A,raw_customers!F:F),raw_branches!A:A,raw_branches!B:B) -> Lankaran Branch | G4: 7888.64 | H4: 9.37 | I4: Active | J4: =IF(I4="Default","Default (Batıq)",IF(H4>=18,"Yüksək Risk",IF(H4>=12,"Orta Risk","Aşağı Risk"))) -> Aşağı Risk
A5: 506 | B5: 366 | C5: =_xlfn.XLOOKUP(B5,raw_customers!A:A,raw_customers!B:B) -> Könül Həsənov | D5: =_xlfn.XLOOKUP(C5,raw_customers!B:B,raw_customers!C:C) -> F | E5: =_xlfn.XLOOKUP(C5,raw_customers!B:B,raw_customers!G:G) -> Premium | F5: =_xlfn.XLOOKUP(_xlfn.XLOOKUP(B5,raw_customers!A:A,raw_customers!F:F),raw_branches!A:A,raw_branches!B:B) -> Baku Central | G5: 57335.63 | H5: 18.56 | I5: Active | J5: =IF(I5="Default","Default (Batıq)",IF(H5>=18,"Yüksək Risk",IF(H5>=12,"Orta Risk","Aşağı Risk"))) -> Yüksək Risk
A6: 507 | B6: 629 | C6: =_xlfn.XLOOKUP(B6,raw_customers!A:A,raw_customers!B:B) -> Zeynəb Rzayev | D6: =_xlfn.XLOOKUP(C6,raw_customers!B:B,raw_customers!C:C) -> F | E6: =_xlfn.XLOOKUP(C6,raw_customers!B:B,raw_customers!G:G) -> Retail | F6: =_xlfn.XLOOKUP(_xlfn.XLOOKUP(B6,raw_customers!A:A,raw_customers!F:F),raw_branches!A:A,raw_branches!B:B) -> Baku Yasamal | G6: 68276.52 | H6: 13.67 | I6: Active | J6: =IF(I6="Default","Default (Batıq)",IF(H6>=18,"Yüksək Risk",IF(H6>=12,"Orta Risk","Aşağı Risk"))) -> Orta Risk
A7: 508 | B7: 934 | C7: =_xlfn.XLOOKUP(B7,raw_customers!A:A,raw_customers!B:B) -> Xəyalə Məmmədov | D7: =_xlfn.XLOOKUP(C7,raw_customers!B:B,raw_customers!C:C) -> F | E7: =_xlfn.XLOOKUP(C7,raw_customers!B:B,raw_customers!G:G) -> Retail | F7: =_xlfn.XLOOKUP(_xlfn.XLOOKUP(B7,raw_customers!A:A,raw_customers!F:F),raw_branches!A:A,raw_branches!B:B) -> Baku Yasamal | G7: 5395.2 | H7: 16.34 | I7: Closed | J7: =IF(I7="Default","Default (Batıq)",IF(H7>=18,"Yüksək Risk",IF(H7>=12,"Orta Risk","Aşağı Risk"))) -> Orta Risk
A8: 509 | B8: 907 | C8: =_xlfn.XLOOKUP(B8,raw_customers!A:A,raw_customers!B:B) -> Fərid Nəbiyev | D8: =_xlfn.XLOOKUP(C8,raw_customers!B:B,raw_customers!C:C) -> M | E8: =_xlfn.XLOOKUP(C8,raw_customers!B:B,raw_customers!G:G) -> Retail | F8: =_xlfn.XLOOKUP(_xlfn.XLOOKUP(B8,raw_customers!A:A,raw_customers!F:F),raw_branches!A:A,raw_branches!B:B) -> Lankaran Branch | G8: 107604.16 | H8: 19.45 | I8: Active | J8: =IF(I8="Default","Default (Batıq)",IF(H8>=18,"Yüksək Risk",IF(H8>=12,"Orta Risk","Aşağı Risk"))) -> Yüksək Risk
A9: 510 | B9: 326 | C9: =_xlfn.XLOOKUP(B9,raw_customers!A:A,raw_customers!B:B) -> Leyla Əzizov | D9: =_xlfn.XLOOKUP(C9,raw_customers!B:B,raw_customers!C:C) -> F | E9: =_xlfn.XLOOKUP(C9,raw_customers!B:B,raw_customers!G:G) -> Retail | F9: =_xlfn.XLOOKUP(_xlfn.XLOOKUP(B9,raw_customers!A:A,raw_customers!F:F),raw_branches!A:A,raw_branches!B:B) -> Lankaran Branch | G9: 7430.32 | H9: 12.87 | I9: Active | J9: =IF(I9="Default","Default (Batıq)",IF(H9>=18,"Yüksək Risk",IF(H9>=12,"Orta Risk","Aşağı Risk"))) -> Orta Risk
A10: 511 | B10: 352 | C10: =_xlfn.XLOOKUP(B10,raw_customers!A:A,raw_customers!B:B) -> Vəfa Orucov | D10: =_xlfn.XLOOKUP(C10,raw_customers!B:B,raw_customers!C:C) -> F | E10: =_xlfn.XLOOKUP(C10,raw_customers!B:B,raw_customers!G:G) -> SME | F10: =_xlfn.XLOOKUP(_xlfn.XLOOKUP(B10,raw_customers!A:A,raw_customers!F:F),raw_branches!A:A,raw_branches!B:B) -> Lankaran Branch | G10: 99322.46 | H10: 14.86 | I10: Closed | J10: =IF(I10="Default","Default (Batıq)",IF(H10>=18,"Yüksək Risk",IF(H10>=12,"Orta Risk","Aşağı Risk"))) -> Orta Risk
A11: 512 | B11: 979 | C11: =_xlfn.XLOOKUP(B11,raw_customers!A:A,raw_customers!B:B) -> Nərgiz Novruzov | D11: =_xlfn.XLOOKUP(C11,raw_customers!B:B,raw_customers!C:C) -> F | E11: =_xlfn.XLOOKUP(C11,raw_customers!B:B,raw_customers!G:G) -> SME | F11: =_xlfn.XLOOKUP(_xlfn.XLOOKUP(B11,raw_customers!A:A,raw_customers!F:F),raw_branches!A:A,raw_branches!B:B) -> Baku Central | G11: 14436.78 | H11: 7.81 | I11: Active | J11: =IF(I11="Default","Default (Batıq)",IF(H11>=18,"Yüksək Risk",IF(H11>=12,"Orta Risk","Aşağı Risk"))) -> Aşağı Risk
A12: 513 | B12: 708 | C12: =_xlfn.XLOOKUP(B12,raw_customers!A:A,raw_customers!B:B) -> Röya Əliyev | D12: =_xlfn.XLOOKUP(C12,raw_customers!B:B,raw_customers!C:C) -> F | E12: =_xlfn.XLOOKUP(C12,raw_customers!B:B,raw_customers!G:G) -> Retail | F12: =_xlfn.XLOOKUP(_xlfn.XLOOKUP(B12,raw_customers!A:A,raw_customers!F:F),raw_branches!A:A,raw_branches!B:B) -> Baku Yasamal | G12: 106322.24 | H12: 8.32 | I12: Closed | J12: =IF(I12="Default","Default (Batıq)",IF(H12>=18,"Yüksək Risk",IF(H12>=12,"Orta Risk","Aşağı Risk"))) -> Aşağı Risk
A13: 514 | B13: 243 | C13: =_xlfn.XLOOKUP(B13,raw_customers!A:A,raw_customers!B:B) -> Ramin Bağırov | D13: =_xlfn.XLOOKUP(C13,raw_customers!B:B,raw_customers!C:C) -> M | E13: =_xlfn.XLOOKUP(C13,raw_customers!B:B,raw_customers!G:G) -> SME | F13: =_xlfn.XLOOKUP(_xlfn.XLOOKUP(B13,raw_customers!A:A,raw_customers!F:F),raw_branches!A:A,raw_branches!B:B) -> Sheki Branch | G13: 136314.96 | H13: 11.88 | I13: Active | J13: =IF(I13="Default","Default (Batıq)",IF(H13>=18,"Yüksək Risk",IF(H13>=12,"Orta Risk","Aşağı Risk"))) -> Aşağı Risk
... A1301: 877 | B1301: 661 | C1301: =_xlfn.XLOOKUP(B1301,raw_customers!A:A,raw_customers!B:B) -> Kənan Cəfərov | D1301: =_xlfn.XLOOKUP(C1301,raw_customers!B:B,raw_customers!C:C) -> M | E1301: =_xlfn.XLOOKUP(C1301,raw_customers!B:B,raw_customers!G:G) -> Premium | F1301: =_xlfn.XLOOKUP(_xlfn.XLOOKUP(B1301,raw_customers!A:A,raw_customers!F:F),raw_branches!A:A,raw_branches!B:B) -> Sumgait Branch | G1301: 69139.55 | H1301: 12.58 | I1301: Default | J1301: =IF(I1301="Default","Default (Batıq)",IF(H1301>=18,"Yüksək Risk",IF(H1301>=12,"Orta Risk","Aşağı Risk"))) -> Default (Batıq)

Sheet kpi_summary
A1: Ümumi Portfel Məbləği: | B1: =SUM(analytics_data!G:G) -> 61454831
A2: Ümumi Kredit Sayı: | B2: =COUNTA(analytics_data!A:A)-1 -> 1300
A3: Ortalama Kredit Məbləği: | B3: =AVERAGE(analytics_data!G:G) -> 47272.947
A4: Ortalama Faiz Dərəcəsi: | B4: =AVERAGE(analytics_data!H:H) -> 13.418308
A5: Default Kredit Sayı: | B5: =COUNTIF(analytics_data!I:I,"Default") -> 128
A6: Default Məbləği: | B6: =SUMIF(analytics_data!I:I,"Default",analytics_data!G:G) -> 5291947.7
A7: Yüksək Riskli Kredit Sayı: | B7: =COUNTIF(analytics_data!J:J,"Yüksək Risk") -> 273
A8: Bakı Filialının Default Məbləği: | B8: =SUMIFS(analytics_data!G:G,analytics_data!F:F,"Baku Yasamal",analytics_data!I:I,"Default") -> 520639.49

Sheet pivot table1
A1: Loan Status | B1: (ALL)
E2: Sum of Loan Amount | F2: Risk Category
A3: Branch Name | B3: Sum of Loan Amount | C3: Count of LOAN_ID | E3: Customer Segment | F3: Aşağı Risk | G3: Default (Batıq) | H3: Orta Risk | I3: Yüksək Risk | J3: Grand Total
A4: Baku Central | B4: 171293 | C4: 195 | E4: Retail | F4: 203530 | G4: 60940 | H4: 3823 | I4: 344617 | J4: 612910
A5: Baku Yasamal | B5: 126473 | C5: 206 | E5: SME | F5: 190684 | G5: 113414 | H5: 13059 | I5: 10528 | J5: 327685
A6: Ganja Branch | B6: 190516 | C6: 190 | E6: Grand Total | F6: 394214 | G6: 174354 | H6: 16882 | I6: 355145 | J6: 940595
A7: Lankaran Branch | B7: 82697 | C7: 162
A8: Mingachevir Branch | B8: 11045 | C8: 191
A9: Sheki Branch | B9: 326934 | C9: 155
A10: Sumgait Branch | B10: 31637 | C10: 201
A11: Grand Total | B11: 940595 | C11: 1300

Sheet monthly loan portfolio trend
A3: Years (FIXED-START_DATE) | B3: FIXED-START_DATE | C3: Sum of FIXED_LOAN_AMOUNT
A4: 2020
B5: Jan | C5: 634514.17
B6: Feb | C6: 794285.75
B7: Mar | C7: 925804.31
B8: Apr | C8: 1045595.5
B9: May | C9: 1234521.9
B10: Jun | C10: 1715549.3
B11: Jul | C11: 1151595.8
B12: Aug | C12: 783593.98
B13: Sep | C13: 639286.64
B14: Oct | C14: 684050.18
B15: Nov | C15: 1054531.9
B16: Dec | C16: 722831.74
A17: 2021
B18: Jan | C18: 965843.16
B19: Feb | C19: 725695.5
B20: Mar | C20: 1394894.9
B21: Apr | C21: 876423.19
B22: May | C22: 1340895
B23: Jun | C23: 530049.28
B24: Jul | C24: 888773.94
B25: Aug | C25: 1167187.9
B26: Sep | C26: 741566.46
B27: Oct | C27: 510068.58
B28: Nov | C28: 1175554.3
B29: Dec | C29: 600244.94
A30: 2022
B31: Jan | C31: 604313.48
B32: Feb | C32: 978237.9
B33: Mar | C33: 717521.46
B34: Apr | C34: 1453272.5
B35: May | C35: 621683.73
B36: Jun | C36: 1241682.2
B37: Jul | C37: 728038.11
B38: Aug | C38: 982625.56
B39: Sep | C39: 1137263.1
B40: Oct | C40: 481404.95
B41: Nov | C41: 729468.11
B42: Dec | C42: 1032357.7
...
